Traceback (most recent call last):
  File "/opt/anaconda3/lib/python3.7/site-packages/jupyter_cache/executors/utils.py", line 56, in single_nb_execution
    record_timing=False,
  File "/opt/anaconda3/lib/python3.7/site-packages/nbclient/client.py", line 1112, in execute
    return NotebookClient(nb=nb, resources=resources, km=km, **kwargs).execute()
  File "/opt/anaconda3/lib/python3.7/site-packages/nbclient/util.py", line 74, in wrapped
    return just_run(coro(*args, **kwargs))
  File "/opt/anaconda3/lib/python3.7/site-packages/nbclient/util.py", line 53, in just_run
    return loop.run_until_complete(coro)
  File "/opt/anaconda3/lib/python3.7/asyncio/base_events.py", line 587, in run_until_complete
    return future.result()
  File "/opt/anaconda3/lib/python3.7/site-packages/nbclient/client.py", line 554, in async_execute
    cell, index, execution_count=self.code_cells_executed + 1
  File "/opt/anaconda3/lib/python3.7/site-packages/nbclient/client.py", line 857, in async_execute_cell
    self._check_raise_for_error(cell, exec_reply)
  File "/opt/anaconda3/lib/python3.7/site-packages/nbclient/client.py", line 760, in _check_raise_for_error
    raise CellExecutionError.from_cell_and_msg(cell, exec_reply_content)
nbclient.exceptions.CellExecutionError: An error occurred while executing the following cell:
------------------
read.table(
  'https://stats.idre.ucla.edu/stat/data/hsb2.csv',
  header = TRUE,
  sep = ","
  ) -> hsb2

factor(hsb2$female,
       levels = c(0, 1),
       labels = c("Male", "Female")
       ) -> hsb2$female 

factor(hsb2$race,
       levels = c(1:4),
       labels = c("Hispanic", "Asian", "African American", "White")
       ) -> hsb2$race

factor(hsb2$ses,
       levels = c(1:3),
       labels = c("Low", "Middle", "High")
       ) -> hsb2$ses

factor(hsb2$schtyp,
       levels = c(1:2),
       labels = c("Public", "Private")
       ) -> hsb2$schtyp

factor(hsb2$prog,
       levels = c(1:3),
       labels = c("General", "Academic", "Vocational")
       ) -> hsb2$prog

save(
  hsb2, file = here::here("data", "hsb2.RData")
  )
------------------

Error in gzfile(file, "wb"): cannot open the connection
Traceback:

1. save(hsb2, file = here::here("data", "hsb2.RData"))
2. gzfile(file, "wb")
ERROR: Error in gzfile(file, "wb"): cannot open the connection


